<?xml version="1.0" ?>
<!-- =================================================================================== -->
<!-- |    This document was autogenerated by xacro from /home/manoja/msp2/urdf/Angad_Full_Assembly.xacro | -->
<!-- |    EDITING THIS FILE BY HAND IS NOT RECOMMENDED                                 | -->
<!-- =================================================================================== -->
<robot name="Angad_Full_Assembly">
  <material name="silver">
    <color rgba="0.700 0.700 0.700 1.000"/>
  </material>
  <transmission name="hip_pitch_l_tran">
    <type>transmission_interface/SimpleTransmission</type>
    <joint name="hip_pitch_l">
      <hardwareInterface>hardware_interface/EffortJointInterface</hardwareInterface>
    </joint>
    <actuator name="hip_pitch_l_actr">
      <hardwareInterface>hardware_interface/EffortJointInterface</hardwareInterface>
      <mechanicalReduction>1</mechanicalReduction>
    </actuator>
  </transmission>
  <transmission name="hip_pitch_r_tran">
    <type>transmission_interface/SimpleTransmission</type>
    <joint name="hip_pitch_r">
      <hardwareInterface>hardware_interface/EffortJointInterface</hardwareInterface>
    </joint>
    <actuator name="hip_pitch_r_actr">
      <hardwareInterface>hardware_interface/EffortJointInterface</hardwareInterface>
      <mechanicalReduction>1</mechanicalReduction>
    </actuator>
  </transmission>
  <transmission name="thigh_roll_l_tran">
    <type>transmission_interface/SimpleTransmission</type>
    <joint name="thigh_roll_l">
      <hardwareInterface>hardware_interface/EffortJointInterface</hardwareInterface>
    </joint>
    <actuator name="thigh_roll_l_actr">
      <hardwareInterface>hardware_interface/EffortJointInterface</hardwareInterface>
      <mechanicalReduction>1</mechanicalReduction>
    </actuator>
  </transmission>
  <transmission name="thigh_roll_r_tran">
    <type>transmission_interface/SimpleTransmission</type>
    <joint name="thigh_roll_r">
      <hardwareInterface>hardware_interface/EffortJointInterface</hardwareInterface>
    </joint>
    <actuator name="thigh_roll_r_actr">
      <hardwareInterface>hardware_interface/EffortJointInterface</hardwareInterface>
      <mechanicalReduction>1</mechanicalReduction>
    </actuator>
  </transmission>
  <transmission name="thigh_yaw_l_tran">
    <type>transmission_interface/SimpleTransmission</type>
    <joint name="thigh_yaw_l">
      <hardwareInterface>hardware_interface/EffortJointInterface</hardwareInterface>
    </joint>
    <actuator name="thigh_yaw_l_actr">
      <hardwareInterface>hardware_interface/EffortJointInterface</hardwareInterface>
      <mechanicalReduction>1</mechanicalReduction>
    </actuator>
  </transmission>
  <transmission name="thigh_yaw_r_tran">
    <type>transmission_interface/SimpleTransmission</type>
    <joint name="thigh_yaw_r">
      <hardwareInterface>hardware_interface/EffortJointInterface</hardwareInterface>
    </joint>
    <actuator name="thigh_yaw_r_actr">
      <hardwareInterface>hardware_interface/EffortJointInterface</hardwareInterface>
      <mechanicalReduction>1</mechanicalReduction>
    </actuator>
  </transmission>
  <transmission name="knee_pitch_l_tran">
    <type>transmission_interface/SimpleTransmission</type>
    <joint name="knee_pitch_l">
      <hardwareInterface>hardware_interface/EffortJointInterface</hardwareInterface>
    </joint>
    <actuator name="knee_pitch_l_actr">
      <hardwareInterface>hardware_interface/EffortJointInterface</hardwareInterface>
      <mechanicalReduction>1</mechanicalReduction>
    </actuator>
  </transmission>
  <transmission name="knee_pitch_r_tran">
    <type>transmission_interface/SimpleTransmission</type>
    <joint name="knee_pitch_r">
      <hardwareInterface>hardware_interface/EffortJointInterface</hardwareInterface>
    </joint>
    <actuator name="knee_pitch_r_actr">
      <hardwareInterface>hardware_interface/EffortJointInterface</hardwareInterface>
      <mechanicalReduction>1</mechanicalReduction>
    </actuator>
  </transmission>
  <transmission name="ankle_pitch_l_tran">
    <type>transmission_interface/SimpleTransmission</type>
    <joint name="ankle_pitch_l">
      <hardwareInterface>hardware_interface/EffortJointInterface</hardwareInterface>
    </joint>
    <actuator name="ankle_pitch_l_actr">
      <hardwareInterface>hardware_interface/EffortJointInterface</hardwareInterface>
      <mechanicalReduction>1</mechanicalReduction>
    </actuator>
  </transmission>
  <transmission name="ankle_pitch_r_tran">
    <type>transmission_interface/SimpleTransmission</type>
    <joint name="ankle_pitch_r">
      <hardwareInterface>hardware_interface/EffortJointInterface</hardwareInterface>
    </joint>
    <actuator name="ankle_pitch_r_actr">
      <hardwareInterface>hardware_interface/EffortJointInterface</hardwareInterface>
      <mechanicalReduction>1</mechanicalReduction>
    </actuator>
  </transmission>
  <transmission name="ankle_roll_l_tran">
    <type>transmission_interface/SimpleTransmission</type>
    <joint name="ankle_roll_l">
      <hardwareInterface>hardware_interface/EffortJointInterface</hardwareInterface>
    </joint>
    <actuator name="ankle_roll_l_actr">
      <hardwareInterface>hardware_interface/EffortJointInterface</hardwareInterface>
      <mechanicalReduction>1</mechanicalReduction>
    </actuator>
  </transmission>
  <transmission name="ankle_roll_r_tran">
    <type>transmission_interface/SimpleTransmission</type>
    <joint name="ankle_roll_r">
      <hardwareInterface>hardware_interface/EffortJointInterface</hardwareInterface>
    </joint>
    <actuator name="ankle_roll_r_actr">
      <hardwareInterface>hardware_interface/EffortJointInterface</hardwareInterface>
      <mechanicalReduction>1</mechanicalReduction>
    </actuator>
  </transmission>
  <transmission name="torso_yaw_tran">
    <type>transmission_interface/SimpleTransmission</type>
    <joint name="torso_yaw">
      <hardwareInterface>hardware_interface/EffortJointInterface</hardwareInterface>
    </joint>
    <actuator name="torso_yaw_actr">
      <hardwareInterface>hardware_interface/EffortJointInterface</hardwareInterface>
      <mechanicalReduction>1</mechanicalReduction>
    </actuator>
  </transmission>
  <transmission name="elbow_pitch_l_tran">
    <type>transmission_interface/SimpleTransmission</type>
    <joint name="elbow_pitch_l">
      <hardwareInterface>hardware_interface/EffortJointInterface</hardwareInterface>
    </joint>
    <actuator name="elbow_pitch_l_actr">
      <hardwareInterface>hardware_interface/EffortJointInterface</hardwareInterface>
      <mechanicalReduction>1</mechanicalReduction>
    </actuator>
  </transmission>
  <transmission name="elbow_pitch_r_tran">
    <type>transmission_interface/SimpleTransmission</type>
    <joint name="elbow_pitch_r">
      <hardwareInterface>hardware_interface/EffortJointInterface</hardwareInterface>
    </joint>
    <actuator name="elbow_pitch_r_actr">
      <hardwareInterface>hardware_interface/EffortJointInterface</hardwareInterface>
      <mechanicalReduction>1</mechanicalReduction>
    </actuator>
  </transmission>
  <transmission name="shoulder_pitch_l_tran">
    <type>transmission_interface/SimpleTransmission</type>
    <joint name="shoulder_pitch_l">
      <hardwareInterface>hardware_interface/EffortJointInterface</hardwareInterface>
    </joint>
    <actuator name="shoulder_pitch_l_actr">
      <hardwareInterface>hardware_interface/EffortJointInterface</hardwareInterface>
      <mechanicalReduction>1</mechanicalReduction>
    </actuator>
  </transmission>
  <transmission name="shoulder_roll_l_tran">
    <type>transmission_interface/SimpleTransmission</type>
    <joint name="shoulder_roll_l">
      <hardwareInterface>hardware_interface/EffortJointInterface</hardwareInterface>
    </joint>
    <actuator name="shoulder_roll_l_actr">
      <hardwareInterface>hardware_interface/EffortJointInterface</hardwareInterface>
      <mechanicalReduction>1</mechanicalReduction>
    </actuator>
  </transmission>
  <transmission name="elbow_yaw_l_tran">
    <type>transmission_interface/SimpleTransmission</type>
    <joint name="elbow_yaw_l">
      <hardwareInterface>hardware_interface/EffortJointInterface</hardwareInterface>
    </joint>
    <actuator name="elbow_yaw_l_actr">
      <hardwareInterface>hardware_interface/EffortJointInterface</hardwareInterface>
      <mechanicalReduction>1</mechanicalReduction>
    </actuator>
  </transmission>
  <transmission name="shoulder_pitch_r_tran">
    <type>transmission_interface/SimpleTransmission</type>
    <joint name="shoulder_pitch_r">
      <hardwareInterface>hardware_interface/EffortJointInterface</hardwareInterface>
    </joint>
    <actuator name="shoulder_pitch_r_actr">
      <hardwareInterface>hardware_interface/EffortJointInterface</hardwareInterface>
      <mechanicalReduction>1</mechanicalReduction>
    </actuator>
  </transmission>
  <transmission name="shoulder_roll_r_tran">
    <type>transmission_interface/SimpleTransmission</type>
    <joint name="shoulder_roll_r">
      <hardwareInterface>hardware_interface/EffortJointInterface</hardwareInterface>
    </joint>
    <actuator name="shoulder_roll_r_actr">
      <hardwareInterface>hardware_interface/EffortJointInterface</hardwareInterface>
      <mechanicalReduction>1</mechanicalReduction>
    </actuator>
  </transmission>
  <transmission name="elbow_yaw_r_tran">
    <type>transmission_interface/SimpleTransmission</type>
    <joint name="elbow_yaw_r">
      <hardwareInterface>hardware_interface/EffortJointInterface</hardwareInterface>
    </joint>
    <actuator name="elbow_yaw_r_actr">
      <hardwareInterface>hardware_interface/EffortJointInterface</hardwareInterface>
      <mechanicalReduction>1</mechanicalReduction>
    </actuator>
  </transmission>
  <gazebo>
    <plugin filename="libgz_ros2_control-system.so" name="gz_ros2_control::GazeboSimROS2ControlPlugin">
      <parameters>/home/manoja/msp2/install/Angad_Full_Assembly_description/share/Angad_Full_Assembly_description/config/ros2_controllers.yaml</parameters>
    </plugin>
    <plugin filename="gz-sim-imu-system" name="gz::sim::systems::Imu">
  </plugin>
  </gazebo>
  <gazebo reference="base_link">
    <material>Gazebo/Silver</material>
    <mu1>0.2</mu1>
    <mu2>0.2</mu2>
    <self_collide>true</self_collide>
    <gravity>true</gravity>
  </gazebo>
  <gazebo reference="hip_L_1">
    <material>Gazebo/Silver</material>
    <mu1>0.2</mu1>
    <mu2>0.2</mu2>
    <self_collide>true</self_collide>
  </gazebo>
  <gazebo reference="hip_R_1">
    <material>Gazebo/Silver</material>
    <mu1>0.2</mu1>
    <mu2>0.2</mu2>
    <self_collide>true</self_collide>
  </gazebo>
  <gazebo reference="thigh_L_1">
    <material>Gazebo/Silver</material>
    <mu1>0.2</mu1>
    <mu2>0.2</mu2>
    <self_collide>true</self_collide>
  </gazebo>
  <gazebo reference="thigh_R_1">
    <material>Gazebo/Silver</material>
    <mu1>0.2</mu1>
    <mu2>0.2</mu2>
    <self_collide>true</self_collide>
  </gazebo>
  <gazebo reference="upper_knee_L_1">
    <material>Gazebo/Silver</material>
    <mu1>0.2</mu1>
    <mu2>0.2</mu2>
    <self_collide>true</self_collide>
  </gazebo>
  <gazebo reference="upper_knee_R_1">
    <material>Gazebo/Silver</material>
    <mu1>0.2</mu1>
    <mu2>0.2</mu2>
    <self_collide>true</self_collide>
  </gazebo>
  <gazebo reference="lower_knee_L_1">
    <material>Gazebo/Silver</material>
    <mu1>0.2</mu1>
    <mu2>0.2</mu2>
    <self_collide>true</self_collide>
  </gazebo>
  <gazebo reference="lower_knee_R_1">
    <material>Gazebo/Silver</material>
    <mu1>0.2</mu1>
    <mu2>0.2</mu2>
    <self_collide>true</self_collide>
  </gazebo>
  <gazebo reference="ankle_L_1">
    <material>Gazebo/Silver</material>
    <mu1>0.2</mu1>
    <mu2>0.2</mu2>
    <self_collide>true</self_collide>
  </gazebo>
  <gazebo reference="ankle_R_1">
    <material>Gazebo/Silver</material>
    <mu1>0.2</mu1>
    <mu2>0.2</mu2>
    <self_collide>true</self_collide>
  </gazebo>
  <gazebo reference="feet_L_1">
    <material>Gazebo/Silver</material>
    <mu1>2.0</mu1>
    <mu2>2.0</mu2>
    <self_collide>true</self_collide>
  </gazebo>
  <gazebo reference="feet_R_1">
    <material>Gazebo/Silver</material>
    <mu1>2.0</mu1>
    <mu2>2.0</mu2>
    <self_collide>true</self_collide>
  </gazebo>
  <gazebo reference="Torso_1">
    <material>Gazebo/Silver</material>
    <mu1>0.2</mu1>
    <mu2>0.2</mu2>
    <self_collide>true</self_collide>
    <sensor name="imu_sensor" type="imu">
      <always_on>1</always_on>
      <update_rate>100</update_rate>
      <visualize>true</visualize>
      <topic>imu</topic>
    </sensor>
  </gazebo>
  <gazebo reference="wrist_L_1">
    <material>Gazebo/Silver</material>
    <mu1>0.2</mu1>
    <mu2>0.2</mu2>
    <self_collide>true</self_collide>
  </gazebo>
  <gazebo reference="wrist_R_1">
    <material>Gazebo/Silver</material>
    <mu1>0.2</mu1>
    <mu2>0.2</mu2>
    <self_collide>true</self_collide>
  </gazebo>
  <gazebo reference="shoulder_pitch_L_1">
    <material>Gazebo/Silver</material>
    <mu1>0.2</mu1>
    <mu2>0.2</mu2>
    <self_collide>true</self_collide>
  </gazebo>
  <gazebo reference="shoulder_roll_L_1">
    <material>Gazebo/Silver</material>
    <mu1>0.2</mu1>
    <mu2>0.2</mu2>
    <self_collide>true</self_collide>
  </gazebo>
  <gazebo reference="bicep_L_1">
    <material>Gazebo/Silver</material>
    <mu1>0.2</mu1>
    <mu2>0.2</mu2>
    <self_collide>true</self_collide>
  </gazebo>
  <gazebo reference="shoulder_pitch_R_1">
    <material>Gazebo/Silver</material>
    <mu1>0.2</mu1>
    <mu2>0.2</mu2>
    <self_collide>true</self_collide>
  </gazebo>
  <gazebo reference="shoulder_roll_R_1">
    <material>Gazebo/Silver</material>
    <mu1>0.2</mu1>
    <mu2>0.2</mu2>
    <self_collide>true</self_collide>
  </gazebo>
  <gazebo reference="bicep_R_1">
    <material>Gazebo/Silver</material>
    <mu1>0.2</mu1>
    <mu2>0.2</mu2>
    <self_collide>true</self_collide>
  </gazebo>
  <link name="base_link">
    <inertial>
      <origin rpy="0 0 0" xyz="0.002978049443025171 3.331729238924102e-05 0.8249140352934465"/>
      <mass value="5.565"/>
      <inertia ixx="0.0272538" ixy="0" ixz="-8.63068e-05" iyy="0.0301722" iyz="-6.3931e-06" izz="0.0318504"/>
    </inertial>
    <visual>
      <origin rpy="0 0 0" xyz="0 0 0"/>
      <geometry>
        <mesh filename="file:///home/manoja/msp2/install/Angad_Full_Assembly_description/share/Angad_Full_Assembly_description/meshes/base_link.stl" scale="0.001 0.001 0.001"/>
      </geometry>
      <material name="silver"/>
    </visual>
    <collision>
      <origin rpy="0 0 0" xyz="0 0 0"/>
      <geometry>
        <mesh filename="file:///home/manoja/msp2/install/Angad_Full_Assembly_description/share/Angad_Full_Assembly_description/meshes/base_link.stl" scale="0.001 0.001 0.001"/>
      </geometry>
    </collision>
  </link>
  <link name="hip_L_1">
    <inertial>
      <origin rpy="0 0 0" xyz="0.03854907436256218 -0.00377537649362079 -0.014028849509831631"/>
      <mass value="1.008"/>
      <inertia ixx="0.00115998" ixy="0.000204833" ixz="0.000311702" iyy="0.00157855" iyz="-7.34726e-05" izz="0.00190361"/>
    </inertial>
    <visual>
      <origin rpy="0 0 0" xyz="-0.06406 -0.0 -0.80394"/>
      <geometry>
        <mesh filename="file:///home/manoja/msp2/install/Angad_Full_Assembly_description/share/Angad_Full_Assembly_description/meshes/hip_L_1.stl" scale="0.001 0.001 0.001"/>
      </geometry>
      <material name="silver"/>
    </visual>
    <collision>
      <origin rpy="0 0 0" xyz="-0.06406 -0.0 -0.80394"/>
      <geometry>
        <mesh filename="file:///home/manoja/msp2/install/Angad_Full_Assembly_description/share/Angad_Full_Assembly_description/meshes/hip_L_1.stl" scale="0.001 0.001 0.001"/>
      </geometry>
    </collision>
  </link>
  <link name="hip_R_1">
    <inertial>
      <origin rpy="0 0 0" xyz="-0.038552261262815704 -0.003775357521075904 -0.014020100360895404"/>
      <mass value="1.008"/>
      <inertia ixx="0.00115998" ixy="-0.000204833" ixz="-0.000311702" iyy="0.00157855" iyz="-7.34726e-05" izz="0.00190361"/>
    </inertial>
    <visual>
      <origin rpy="0 0 0" xyz="0.06406 -0.0 -0.80394"/>
      <geometry>
        <mesh filename="file:///home/manoja/msp2/install/Angad_Full_Assembly_description/share/Angad_Full_Assembly_description/meshes/hip_R_1.stl" scale="0.001 0.001 0.001"/>
      </geometry>
      <material name="silver"/>
    </visual>
    <collision>
      <origin rpy="0 0 0" xyz="0.06406 -0.0 -0.80394"/>
      <geometry>
        <mesh filename="file:///home/manoja/msp2/install/Angad_Full_Assembly_description/share/Angad_Full_Assembly_description/meshes/hip_R_1.stl" scale="0.001 0.001 0.001"/>
      </geometry>
    </collision>
  </link>
  <link name="thigh_L_1">
    <inertial>
      <origin rpy="0 0 0" xyz="-1.40174504655588e-05 -0.030115272344603504 -0.08645138758904114"/>
      <mass value="1.319"/>
      <inertia ixx="0.00664321" ixy="8.98835e-06" ixz="1.22568e-05" iyy="0.00731815" iyz="0.000276188" izz="0.00393772"/>
    </inertial>
    <visual>
      <origin rpy="0 0 0" xyz="-0.13829 -0.0315 -0.776903"/>
      <geometry>
        <mesh filename="file:///home/manoja/msp2/install/Angad_Full_Assembly_description/share/Angad_Full_Assembly_description/meshes/thigh_L_1.stl" scale="0.001 0.001 0.001"/>
      </geometry>
      <material name="silver"/>
    </visual>
    <collision>
      <origin rpy="0 0 0" xyz="-0.13829 -0.0315 -0.776903"/>
      <geometry>
        <mesh filename="file:///home/manoja/msp2/install/Angad_Full_Assembly_description/share/Angad_Full_Assembly_description/meshes/thigh_L_1.stl" scale="0.001 0.001 0.001"/>
      </geometry>
    </collision>
  </link>
  <link name="thigh_R_1">
    <inertial>
      <origin rpy="0 0 0" xyz="-0.0020791884572767816 -0.030383815559322697 -0.0863687783674898"/>
      <mass value="1.319"/>
      <inertia ixx="0.00664117" ixy="1.14208e-05" ixz="-7.17876e-05" iyy="0.00719671" iyz="0.000270019" izz="0.00381943"/>
    </inertial>
    <visual>
      <origin rpy="0 0 0" xyz="0.138263 -0.0315 -0.77683"/>
      <geometry>
        <mesh filename="file:///home/manoja/msp2/install/Angad_Full_Assembly_description/share/Angad_Full_Assembly_description/meshes/thigh_R_1.stl" scale="0.001 0.001 0.001"/>
      </geometry>
      <material name="silver"/>
    </visual>
    <collision>
      <origin rpy="0 0 0" xyz="0.138263 -0.0315 -0.77683"/>
      <geometry>
        <mesh filename="file:///home/manoja/msp2/install/Angad_Full_Assembly_description/share/Angad_Full_Assembly_description/meshes/thigh_R_1.stl" scale="0.001 0.001 0.001"/>
      </geometry>
    </collision>
  </link>
  <link name="upper_knee_L_1">
    <inertial>
      <origin rpy="0 0 0" xyz="-0.0013353106898234268 -0.005517962362791416 -0.11408271066504616"/>
      <mass value="2.264"/>
      <inertia ixx="0.0219197" ixy="2.59696e-05" ixz="-0.000475653" iyy="0.0193774" iyz="-0.000436015" izz="0.00704322"/>
    </inertial>
    <visual>
      <origin rpy="0 0 0" xyz="-0.138295 -0.005168 -0.620317"/>
      <geometry>
        <mesh filename="file:///home/manoja/msp2/install/Angad_Full_Assembly_description/share/Angad_Full_Assembly_description/meshes/upper_knee_L_1.stl" scale="0.001 0.001 0.001"/>
      </geometry>
      <material name="silver"/>
    </visual>
    <collision>
      <origin rpy="0 0 0" xyz="-0.138295 -0.005168 -0.620317"/>
      <geometry>
        <mesh filename="file:///home/manoja/msp2/install/Angad_Full_Assembly_description/share/Angad_Full_Assembly_description/meshes/upper_knee_L_1.stl" scale="0.001 0.001 0.001"/>
      </geometry>
    </collision>
  </link>
  <link name="upper_knee_R_1">
    <inertial>
      <origin rpy="0 0 0" xyz="-0.0007904776210841402 -0.005611532850717232 -0.11408357177758233"/>
      <mass value="2.264"/>
      <inertia ixx="0.0219137" ixy="0.00022962" ixz="0.000168115" iyy="0.0193988" iyz="-0.000418237" izz="0.00702938"/>
    </inertial>
    <visual>
      <origin rpy="0 0 0" xyz="0.141977 -0.004808 -0.620349"/>
      <geometry>
        <mesh filename="file:///home/manoja/msp2/install/Angad_Full_Assembly_description/share/Angad_Full_Assembly_description/meshes/upper_knee_R_1.stl" scale="0.001 0.001 0.001"/>
      </geometry>
      <material name="silver"/>
    </visual>
    <collision>
      <origin rpy="0 0 0" xyz="0.141977 -0.004808 -0.620349"/>
      <geometry>
        <mesh filename="file:///home/manoja/msp2/install/Angad_Full_Assembly_description/share/Angad_Full_Assembly_description/meshes/upper_knee_R_1.stl" scale="0.001 0.001 0.001"/>
      </geometry>
    </collision>
  </link>
  <link name="lower_knee_L_1">
    <inertial>
      <origin rpy="0 0 0" xyz="-0.026381467582163642 0.002587818636810185 -0.14748715164304727"/>
      <mass value="1.446"/>
      <inertia ixx="0.0179909" ixy="1.2e-05" ixz="-4.22513e-05" iyy="0.0174857" iyz="0.00187816" izz="0.00337026"/>
    </inertial>
    <visual>
      <origin rpy="0 0 0" xyz="-0.165295 -0.005033 -0.410617"/>
      <geometry>
        <mesh filename="file:///home/manoja/msp2/install/Angad_Full_Assembly_description/share/Angad_Full_Assembly_description/meshes/lower_knee_L_1.stl" scale="0.001 0.001 0.001"/>
      </geometry>
      <material name="silver"/>
    </visual>
    <collision>
      <origin rpy="0 0 0" xyz="-0.165295 -0.005033 -0.410617"/>
      <geometry>
        <mesh filename="file:///home/manoja/msp2/install/Angad_Full_Assembly_description/share/Angad_Full_Assembly_description/meshes/lower_knee_L_1.stl" scale="0.001 0.001 0.001"/>
      </geometry>
    </collision>
  </link>
  <link name="lower_knee_R_1">
    <inertial>
      <origin rpy="0 0 0" xyz="0.02249291366303005 0.004807172510886975 -0.14807185562679898"/>
      <mass value="1.446"/>
      <inertia ixx="0.0179724" ixy="0.000133" ixz="-0.000495439" iyy="0.0175592" iyz="0.00182317" izz="0.00343161"/>
    </inertial>
    <visual>
      <origin rpy="0 0 0" xyz="0.172267 -0.001544 -0.411313"/>
      <geometry>
        <mesh filename="file:///home/manoja/msp2/install/Angad_Full_Assembly_description/share/Angad_Full_Assembly_description/meshes/lower_knee_R_1.stl" scale="0.001 0.001 0.001"/>
      </geometry>
      <material name="silver"/>
    </visual>
    <collision>
      <origin rpy="0 0 0" xyz="0.172267 -0.001544 -0.411313"/>
      <geometry>
        <mesh filename="file:///home/manoja/msp2/install/Angad_Full_Assembly_description/share/Angad_Full_Assembly_description/meshes/lower_knee_R_1.stl" scale="0.001 0.001 0.001"/>
      </geometry>
    </collision>
  </link>
  <link name="ankle_L_1">
    <inertial>
      <origin rpy="0 0 0" xyz="-0.029486478549063777 0.001377277986068716 4.950374079513986e-06"/>
      <mass value="0.10759548262439121"/>
      <inertia ixx="1.6e-05" ixy="-0.0" ixz="-0.0" iyy="3.8e-05" iyz="-0.0" izz="5.1e-05"/>
    </inertial>
    <visual>
      <origin rpy="0 0 0" xyz="-0.169321 -0.030731 -0.047638"/>
      <geometry>
        <mesh filename="file:///home/manoja/msp2/install/Angad_Full_Assembly_description/share/Angad_Full_Assembly_description/meshes/ankle_L_1.stl" scale="0.001 0.001 0.001"/>
      </geometry>
      <material name="silver"/>
    </visual>
    <collision>
      <origin rpy="0 0 0" xyz="-0.169321 -0.030731 -0.047638"/>
      <geometry>
        <mesh filename="file:///home/manoja/msp2/install/Angad_Full_Assembly_description/share/Angad_Full_Assembly_description/meshes/ankle_L_1.stl" scale="0.001 0.001 0.001"/>
      </geometry>
    </collision>
  </link>
  <link name="ankle_R_1">
    <inertial>
      <origin rpy="0 0 0" xyz="0.029175110656741804 0.004434380289984066 -0.0006992377379477013"/>
      <mass value="0.1075954826243918"/>
      <inertia ixx="1.6e-05" ixy="-2e-06" ixz="1e-06" iyy="3.8e-05" iyz="0.0" izz="5.1e-05"/>
    </inertial>
    <visual>
      <origin rpy="0 0 0" xyz="0.187464 -0.025444 -0.048506"/>
      <geometry>
        <mesh filename="file:///home/manoja/msp2/install/Angad_Full_Assembly_description/share/Angad_Full_Assembly_description/meshes/ankle_R_1.stl" scale="0.001 0.001 0.001"/>
      </geometry>
      <material name="silver"/>
    </visual>
    <collision>
      <origin rpy="0 0 0" xyz="0.187464 -0.025444 -0.048506"/>
      <geometry>
        <mesh filename="file:///home/manoja/msp2/install/Angad_Full_Assembly_description/share/Angad_Full_Assembly_description/meshes/ankle_R_1.stl" scale="0.001 0.001 0.001"/>
      </geometry>
    </collision>
  </link>
  <link name="feet_L_1">
    <inertial>
      <origin rpy="0 0 0" xyz="1.4590627572308446e-05 -0.030224126757618437 -0.025368031084606422"/>
      <mass value="0.365"/>
      <inertia ixx="0.000967774" ixy="2.4e-05" ixz="-0" iyy="0.000266357" iyz="1.60238e-05" izz="0.0010612"/>
    </inertial>
    <visual>
      <origin rpy="0 0 0" xyz="-0.141356 -0.069456 -0.047775"/>
      <geometry>
        <mesh filename="file:///home/manoja/msp2/install/Angad_Full_Assembly_description/share/Angad_Full_Assembly_description/meshes/feet_L_1.stl" scale="0.001 0.001 0.001"/>
      </geometry>
      <material name="silver"/>
    </visual>
    <collision>
      <origin rpy="0 0 0" xyz="-0.141356 -0.069456 -0.047775"/>
      <geometry>
        <mesh filename="file:///home/manoja/msp2/install/Angad_Full_Assembly_description/share/Angad_Full_Assembly_description/meshes/feet_L_1.stl" scale="0.001 0.001 0.001"/>
      </geometry>
    </collision>
  </link>
  <link name="feet_R_1">
    <inertial>
      <origin rpy="0 0 0" xyz="0.0026047017550297202 -0.030217438377113798 -0.025242270995119415"/>
      <mass value="0.365"/>
      <inertia ixx="0.000958402" ixy="8.13281e-05" ixz="0" iyy="0.000276032" iyz="1.90471e-05" izz="0.00106089"/>
    </inertial>
    <visual>
      <origin rpy="0 0 0" xyz="0.163716 -0.067164 -0.047827"/>
      <geometry>
        <mesh filename="file:///home/manoja/msp2/install/Angad_Full_Assembly_description/share/Angad_Full_Assembly_description/meshes/feet_R_1.stl" scale="0.001 0.001 0.001"/>
      </geometry>
      <material name="silver"/>
    </visual>
    <collision>
      <origin rpy="0 0 0" xyz="0.163716 -0.067164 -0.047827"/>
      <geometry>
        <mesh filename="file:///home/manoja/msp2/install/Angad_Full_Assembly_description/share/Angad_Full_Assembly_description/meshes/feet_R_1.stl" scale="0.001 0.001 0.001"/>
      </geometry>
    </collision>
  </link>
  <link name="Torso_1">
    <inertial>
      <origin rpy="0 0 0" xyz="0.0012771309079774086 -0.001683956790175145 0.23828496110377373"/>
      <mass value="4.529"/>
      <inertia ixx="0.0917624" ixy="-0.000780409" ixz="0.000264244" iyy="0.122035" iyz="0.000501789" izz="0.0641058"/>
    </inertial>
    <visual>
      <origin rpy="0 0 0" xyz="0.0 -0.0 -0.883471"/>
      <geometry>
        <mesh filename="file:///home/manoja/msp2/install/Angad_Full_Assembly_description/share/Angad_Full_Assembly_description/meshes/Torso_1.stl" scale="0.001 0.001 0.001"/>
      </geometry>
      <material name="silver"/>
    </visual>
    <collision>
      <origin rpy="0 0 0" xyz="0.0 -0.0 -0.883471"/>
      <geometry>
        <mesh filename="file:///home/manoja/msp2/install/Angad_Full_Assembly_description/share/Angad_Full_Assembly_description/meshes/Torso_1.stl" scale="0.001 0.001 0.001"/>
      </geometry>
    </collision>
  </link>
  <link name="wrist_L_1">
    <inertial>
      <origin rpy="0 0 0" xyz="-0.014597822663228288 -0.00032820857286989906 -0.04785735645922662"/>
      <mass value="0.37"/>
      <inertia ixx="0.00178209" ixy="-1.5e-05" ixz="0.000172451" iyy="0.00196071" iyz="1.7627e-06" izz="0.00063898"/>
    </inertial>
    <visual>
      <origin rpy="0 0 0" xyz="-0.284491 -0.011757 -0.976612"/>
      <geometry>
        <mesh filename="file:///home/manoja/msp2/install/Angad_Full_Assembly_description/share/Angad_Full_Assembly_description/meshes/wrist_L_1.stl" scale="0.001 0.001 0.001"/>
      </geometry>
      <material name="silver"/>
    </visual>
    <collision>
      <origin rpy="0 0 0" xyz="-0.284491 -0.011757 -0.976612"/>
      <geometry>
        <mesh filename="file:///home/manoja/msp2/install/Angad_Full_Assembly_description/share/Angad_Full_Assembly_description/meshes/wrist_L_1.stl" scale="0.001 0.001 0.001"/>
      </geometry>
    </collision>
  </link>
  <link name="wrist_R_1">
    <inertial>
      <origin rpy="0 0 0" xyz="0.018339170582659936 0.0013563551687613635 -0.04850994481380699"/>
      <mass value="0.37"/>
      <inertia ixx="0.00176154" ixy="-7.5e-05" ixz="-0.000232091" iyy="0.00195926" iyz="-3.96611e-05" izz="0.000663075"/>
    </inertial>
    <visual>
      <origin rpy="0 0 0" xyz="0.284622 0.004379 -0.976602"/>
      <geometry>
        <mesh filename="file:///home/manoja/msp2/install/Angad_Full_Assembly_description/share/Angad_Full_Assembly_description/meshes/wrist_R_1.stl" scale="0.001 0.001 0.001"/>
      </geometry>
      <material name="silver"/>
    </visual>
    <collision>
      <origin rpy="0 0 0" xyz="0.284622 0.004379 -0.976602"/>
      <geometry>
        <mesh filename="file:///home/manoja/msp2/install/Angad_Full_Assembly_description/share/Angad_Full_Assembly_description/meshes/wrist_R_1.stl" scale="0.001 0.001 0.001"/>
      </geometry>
    </collision>
  </link>
  <link name="shoulder_pitch_L_1">
    <inertial>
      <origin rpy="0 0 0" xyz="0.07268848630879282 0.00183776562654197 -3.7835069854885717e-07"/>
      <mass value="0.929"/>
      <inertia ixx="0.000771942" ixy="-1.61427e-05" ixz="-0.0" iyy="0.00141377" iyz="-0.0" izz="0.000904634"/>
    </inertial>
    <visual>
      <origin rpy="0 0 0" xyz="-0.142972 -0.003567 -1.207974"/>
      <geometry>
        <mesh filename="file:///home/manoja/msp2/install/Angad_Full_Assembly_description/share/Angad_Full_Assembly_description/meshes/shoulder_pitch_L_1.stl" scale="0.001 0.001 0.001"/>
      </geometry>
      <material name="silver"/>
    </visual>
    <collision>
      <origin rpy="0 0 0" xyz="-0.142972 -0.003567 -1.207974"/>
      <geometry>
        <mesh filename="file:///home/manoja/msp2/install/Angad_Full_Assembly_description/share/Angad_Full_Assembly_description/meshes/shoulder_pitch_L_1.stl" scale="0.001 0.001 0.001"/>
      </geometry>
    </collision>
  </link>
  <link name="shoulder_roll_L_1">
    <inertial>
      <origin rpy="0 0 0" xyz="0.006820681072588153 0.022543983036535473 -0.04196050745358937"/>
      <mass value="0.64"/>
      <inertia ixx="0.0025085" ixy="-1.06618e-06" ixz="0.000212809" iyy="0.00218566" iyz="5.73603e-05" izz="0.00133528"/>
    </inertial>
    <visual>
      <origin rpy="0 0 0" xyz="-0.218947 0.014269 -1.207974"/>
      <geometry>
        <mesh filename="file:///home/manoja/msp2/install/Angad_Full_Assembly_description/share/Angad_Full_Assembly_description/meshes/shoulder_roll_L_1.stl" scale="0.001 0.001 0.001"/>
      </geometry>
      <material name="silver"/>
    </visual>
    <collision>
      <origin rpy="0 0 0" xyz="-0.218947 0.014269 -1.207974"/>
      <geometry>
        <mesh filename="file:///home/manoja/msp2/install/Angad_Full_Assembly_description/share/Angad_Full_Assembly_description/meshes/shoulder_roll_L_1.stl" scale="0.001 0.001 0.001"/>
      </geometry>
    </collision>
  </link>
  <link name="bicep_L_1">
    <inertial>
      <origin rpy="0 0 0" xyz="0.007274821132527365 0.002336663250654977 -0.04402890372206425"/>
      <mass value="0.648"/>
      <inertia ixx="0.00326608" ixy="2.22586e-06" ixz="0.000230748" iyy="0.0030984" iyz="2.52264e-05" izz="0.00204111"/>
    </inertial>
    <visual>
      <origin rpy="0 0 0" xyz="-0.237141 -0.010449 -1.101281"/>
      <geometry>
        <mesh filename="file:///home/manoja/msp2/install/Angad_Full_Assembly_description/share/Angad_Full_Assembly_description/meshes/bicep_L_1.stl" scale="0.001 0.001 0.001"/>
      </geometry>
      <material name="silver"/>
    </visual>
    <collision>
      <origin rpy="0 0 0" xyz="-0.237141 -0.010449 -1.101281"/>
      <geometry>
        <mesh filename="file:///home/manoja/msp2/install/Angad_Full_Assembly_description/share/Angad_Full_Assembly_description/meshes/bicep_L_1.stl" scale="0.001 0.001 0.001"/>
      </geometry>
    </collision>
  </link>
  <link name="shoulder_pitch_R_1">
    <inertial>
      <origin rpy="0 0 0" xyz="-0.07268831266820741 -0.0018371985546969628 -3.7835063526614476e-07"/>
      <mass value="0.929"/>
      <inertia ixx="0.000771942" ixy="-1.61427e-05" ixz="0.0" iyy="0.00141377" iyz="0.0" izz="0.000904634"/>
    </inertial>
    <visual>
      <origin rpy="0 0 0" xyz="0.142971 0.003614 -1.207974"/>
      <geometry>
        <mesh filename="file:///home/manoja/msp2/install/Angad_Full_Assembly_description/share/Angad_Full_Assembly_description/meshes/shoulder_pitch_R_1.stl" scale="0.001 0.001 0.001"/>
      </geometry>
      <material name="silver"/>
    </visual>
    <collision>
      <origin rpy="0 0 0" xyz="0.142971 0.003614 -1.207974"/>
      <geometry>
        <mesh filename="file:///home/manoja/msp2/install/Angad_Full_Assembly_description/share/Angad_Full_Assembly_description/meshes/shoulder_pitch_R_1.stl" scale="0.001 0.001 0.001"/>
      </geometry>
    </collision>
  </link>
  <link name="shoulder_roll_R_1">
    <inertial>
      <origin rpy="0 0 0" xyz="-0.00797108983942904 0.022169593166912808 -0.041956895738376465"/>
      <mass value="0.64"/>
      <inertia ixx="0.00250786" ixy="1.72721e-05" ixz="-0.000214088" iyy="0.00218651" iyz="4.66985e-05" izz="0.00133485"/>
    </inertial>
    <visual>
      <origin rpy="0 0 0" xyz="0.217948 0.025265 -1.207974"/>
      <geometry>
        <mesh filename="file:///home/manoja/msp2/install/Angad_Full_Assembly_description/share/Angad_Full_Assembly_description/meshes/shoulder_roll_R_1.stl" scale="0.001 0.001 0.001"/>
      </geometry>
      <material name="silver"/>
    </visual>
    <collision>
      <origin rpy="0 0 0" xyz="0.217948 0.025265 -1.207974"/>
      <geometry>
        <mesh filename="file:///home/manoja/msp2/install/Angad_Full_Assembly_description/share/Angad_Full_Assembly_description/meshes/shoulder_roll_R_1.stl" scale="0.001 0.001 0.001"/>
      </geometry>
    </collision>
  </link>
  <link name="bicep_R_1">
    <inertial>
      <origin rpy="0 0 0" xyz="-0.008355433029998388 0.0019109890257454605 -0.043859757836306246"/>
      <mass value="0.648"/>
      <inertia ixx="0.00326975" ixy="2.22584e-05" ixz="-0.000218874" iyy="0.00309762" iyz="1.18711e-05" izz="0.00203293"/>
    </inertial>
    <visual>
      <origin rpy="0 0 0" xyz="0.237367 0.001498 -1.101281"/>
      <geometry>
        <mesh filename="file:///home/manoja/msp2/install/Angad_Full_Assembly_description/share/Angad_Full_Assembly_description/meshes/bicep_R_1.stl" scale="0.001 0.001 0.001"/>
      </geometry>
      <material name="silver"/>
    </visual>
    <collision>
      <origin rpy="0 0 0" xyz="0.237367 0.001498 -1.101281"/>
      <geometry>
        <mesh filename="file:///home/manoja/msp2/install/Angad_Full_Assembly_description/share/Angad_Full_Assembly_description/meshes/bicep_R_1.stl" scale="0.001 0.001 0.001"/>
      </geometry>
    </collision>
  </link>
  <joint name="hip_pitch_l" type="revolute">
    <origin rpy="0 0 0" xyz="0.06406 0.0 0.80394"/>
    <parent link="base_link"/>
    <child link="hip_L_1"/>
    <axis xyz="-0.939693 0.0 0.34202"/>
    <limit effort="100.0" lower="-1.57" upper="1.57" velocity="5.0"/>
    <dynamics damping="0.1" friction="0.0"/>
  </joint>
  <joint name="hip_pitch_r" type="revolute">
    <origin rpy="0 0 0" xyz="-0.06406 0.0 0.80394"/>
    <parent link="base_link"/>
    <child link="hip_R_1"/>
    <axis xyz="0.939693 0.0 0.34202"/>
    <limit effort="100.0" lower="-1.57" upper="1.57" velocity="5.0"/>
    <dynamics damping="0.1" friction="0.0"/>
  </joint>
  <joint name="thigh_roll_l" type="revolute">
    <origin rpy="0 0 0" xyz="0.07423 0.0315 -0.027037"/>
    <parent link="hip_L_1"/>
    <child link="thigh_L_1"/>
    <axis xyz="0.0 1.0 0.0"/>
    <limit effort="100.0" lower="-0.5" upper="0.5" velocity="5.0"/>
    <dynamics damping="0.1" friction="0.0"/>
  </joint>
  <joint name="thigh_roll_r" type="revolute">
    <origin rpy="0 0 0" xyz="-0.074203 0.0315 -0.02711"/>
    <parent link="hip_R_1"/>
    <child link="thigh_R_1"/>
    <axis xyz="0.0 1.0 0.0"/>
    <limit effort="100.0" lower="-0.5" upper="0.5" velocity="5.0"/>
    <dynamics damping="0.1" friction="0.0"/>
  </joint>
  <joint name="thigh_yaw_l" type="revolute">
    <origin rpy="0 0 0" xyz="5e-06 -0.026332 -0.156586"/>
    <parent link="thigh_L_1"/>
    <child link="upper_knee_L_1"/>
    <axis xyz="0.0 0.0 -1.0"/>
    <limit effort="100.0" lower="-0.5" upper="0.5" velocity="5.0"/>
    <dynamics damping="0.1" friction="0.0"/>
  </joint>
  <joint name="thigh_yaw_r" type="revolute">
    <origin rpy="0 0 0" xyz="-0.003714 -0.026692 -0.156481"/>
    <parent link="thigh_R_1"/>
    <child link="upper_knee_R_1"/>
    <axis xyz="0.0 0.0 -1.0"/>
    <limit effort="100.0" lower="-0.5" upper="0.5" velocity="5.0"/>
    <dynamics damping="0.1" friction="0.0"/>
  </joint>
  <joint name="knee_pitch_l" type="revolute">
    <origin rpy="0 0 0" xyz="0.027 -0.000135 -0.2097"/>
    <parent link="upper_knee_L_1"/>
    <child link="lower_knee_L_1"/>
    <axis xyz="1.0 0.0 0.0"/>
    <limit effort="100.0" lower="-2.0" upper="2.0" velocity="5.0"/>
    <dynamics damping="0.1" friction="0.0"/>
  </joint>
  <joint name="knee_pitch_r" type="revolute">
    <origin rpy="0 0 0" xyz="-0.03029 -0.003264 -0.209036"/>
    <parent link="upper_knee_R_1"/>
    <child link="lower_knee_R_1"/>
    <axis xyz="1.0 0.0 0.0"/>
    <limit effort="100.0" lower="-2.0" upper="2.0" velocity="5.0"/>
    <dynamics damping="0.1" friction="0.0"/>
  </joint>
  <joint name="ankle_pitch_l" type="revolute">
    <origin rpy="0 0 0" xyz="0.004026 0.025698 -0.362979"/>
    <parent link="lower_knee_L_1"/>
    <child link="ankle_L_1"/>
    <axis xyz="1.0 0.0 0.0"/>
    <limit effort="100.0" lower="-1.0" upper="1.0" velocity="5.0"/>
    <dynamics damping="0.1" friction="0.0"/>
  </joint>
  <joint name="ankle_pitch_r" type="revolute">
    <origin rpy="0 0 0" xyz="-0.015197 0.0239 -0.362807"/>
    <parent link="lower_knee_R_1"/>
    <child link="ankle_R_1"/>
    <axis xyz="1.0 0.0 0.0"/>
    <limit effort="100.0" lower="-1.0" upper="1.0" velocity="5.0"/>
    <dynamics damping="0.1" friction="0.0"/>
  </joint>
  <joint name="ankle_roll_l" type="revolute">
    <origin rpy="0 0 0" xyz="-0.027965 0.038725 0.000137"/>
    <parent link="ankle_L_1"/>
    <child link="feet_L_1"/>
    <axis xyz="0.0 -1.0 0.0"/>
    <limit effort="100.0" lower="-0.5" upper="0.5" velocity="5.0"/>
    <dynamics damping="0.1" friction="0.0"/>
  </joint>
  <joint name="ankle_roll_r" type="revolute">
    <origin rpy="0 0 0" xyz="0.023748 0.04172 -0.000679"/>
    <parent link="ankle_R_1"/>
    <child link="feet_R_1"/>
    <axis xyz="0.0 -1.0 0.0"/>
    <limit effort="100.0" lower="-0.5" upper="0.5" velocity="5.0"/>
    <dynamics damping="0.1" friction="0.0"/>
  </joint>
  <link name="torso_pitch_link">
    <inertial>
      <origin rpy="0 0 0" xyz="0 0 0"/>
      <mass value="0.01"/>
      <inertia ixx="0.0001" ixy="0.0" ixz="0.0" iyy="0.0001" iyz="0.0" izz="0.0001"/>
    </inertial>
  </link>
  <joint name="torso_pitch" type="revolute">
    <origin rpy="0 0 0" xyz="0.0 0.0 0.883471"/>
    <parent link="base_link"/>
    <child link="torso_pitch_link"/>
    <axis xyz="0.0 1.0 0.0"/>
    <limit effort="100.0" lower="-1.57" upper="1.57" velocity="5.0"/>
    <dynamics damping="0.1" friction="0.0"/>
  </joint>
  <link name="torso_roll_link">
    <inertial>
      <origin rpy="0 0 0" xyz="0 0 0"/>
      <mass value="0.01"/>
      <inertia ixx="0.0001" ixy="0.0" ixz="0.0" iyy="0.0001" iyz="0.0" izz="0.0001"/>
    </inertial>
  </link>
  <joint name="torso_roll" type="revolute">
    <origin rpy="0 0 0" xyz="0.0 0.0 0.0"/>
    <parent link="torso_pitch_link"/>
    <child link="torso_roll_link"/>
    <axis xyz="1.0 0.0 0.0"/>
    <limit effort="100.0" lower="-1.57" upper="1.57" velocity="5.0"/>
    <dynamics damping="0.1" friction="0.0"/>
  </joint>
  <joint name="torso_yaw" type="revolute">
    <origin rpy="0 0 0" xyz="0.0 0.0 0.0"/>
    <parent link="torso_roll_link"/>
    <child link="Torso_1"/>
    <axis xyz="-0.0 -0.0 1.0"/>
    <limit effort="100.0" lower="-1.57" upper="1.57" velocity="5.0"/>
    <dynamics damping="0.1" friction="0.0"/>
  </joint>
  <joint name="elbow_pitch_l" type="revolute">
    <origin rpy="0 0 0" xyz="0.04735 0.001308 -0.124669"/>
    <parent link="bicep_L_1"/>
    <child link="wrist_L_1"/>
    <axis xyz="-0.984371 -0.029347 -0.173646"/>
    <limit effort="100.0" lower="-1.57" upper="1.57" velocity="5.0"/>
    <dynamics damping="0.1" friction="0.0"/>
  </joint>
  <joint name="elbow_pitch_r" type="revolute">
    <origin rpy="0 0 0" xyz="-0.047255 -0.002881 -0.124679"/>
    <parent link="bicep_R_1"/>
    <child link="wrist_R_1"/>
    <axis xyz="-0.980548 -0.092247 0.173253"/>
    <limit effort="100.0" lower="-1.57" upper="1.57" velocity="5.0"/>
    <dynamics damping="0.1" friction="0.0"/>
  </joint>
  <joint name="shoulder_pitch_l" type="revolute">
    <origin rpy="0 0 0" xyz="0.142972 0.003567 0.324503"/>
    <parent link="Torso_1"/>
    <child link="shoulder_pitch_L_1"/>
    <axis xyz="0.999681 0.025268 0.0"/>
    <limit effort="100" lower="-3.141593" upper="3.141593" velocity="100"/>
    <dynamics damping="0.1" friction="0.0"/>
  </joint>
  <joint name="shoulder_roll_l" type="revolute">
    <origin rpy="0 0 0" xyz="0.075975 -0.017836 0.0"/>
    <parent link="shoulder_pitch_L_1"/>
    <child link="shoulder_roll_L_1"/>
    <axis xyz="0.025268 -0.999681 -0.0"/>
    <limit effort="100" lower="0.0" upper="2.792527" velocity="100"/>
    <dynamics damping="0.1" friction="0.0"/>
  </joint>
  <joint name="elbow_yaw_l" type="revolute">
    <origin rpy="0 0 0" xyz="0.018194 0.024718 -0.106693"/>
    <parent link="shoulder_roll_L_1"/>
    <child link="bicep_L_1"/>
    <axis xyz="0.173593 0.004388 -0.984808"/>
    <limit effort="100" lower="-3.141593" upper="3.141593" velocity="100"/>
    <dynamics damping="0.1" friction="0.0"/>
  </joint>
  <joint name="shoulder_pitch_r" type="revolute">
    <origin rpy="0 0 0" xyz="-0.142971 -0.003614 0.324503"/>
    <parent link="Torso_1"/>
    <child link="shoulder_pitch_R_1"/>
    <axis xyz="0.999681 0.025268 -0.0"/>
    <limit effort="100" lower="-3.141593" upper="3.141593" velocity="100"/>
    <dynamics damping="0.1" friction="0.0"/>
  </joint>
  <joint name="shoulder_roll_r" type="revolute">
    <origin rpy="0 0 0" xyz="-0.074977 -0.021651 0.0"/>
    <parent link="shoulder_pitch_R_1"/>
    <child link="shoulder_roll_R_1"/>
    <axis xyz="0.025268 -0.999681 -0.0"/>
    <limit effort="100" lower="-2.879793" upper="0.174533" velocity="100"/>
    <dynamics damping="0.1" friction="0.0"/>
  </joint>
  <joint name="elbow_yaw_r" type="revolute">
    <origin rpy="0 0 0" xyz="-0.019419 0.023767 -0.106693"/>
    <parent link="shoulder_roll_R_1"/>
    <child link="bicep_R_1"/>
    <axis xyz="-0.173593 -0.004388 -0.984808"/>
    <limit effort="100" lower="-3.141593" upper="3.141593" velocity="100"/>
    <dynamics damping="0.1" friction="0.0"/>
  </joint>
  <ros2_control name="GazeboSimSystem" type="system">
    <hardware>
      <plugin>gz_ros2_control/GazeboSimSystem</plugin>
    </hardware>
    <joint name="hip_pitch_l">
      <command_interface name="position">
        <param name="min">-3.14</param>
        <param name="max">3.14</param>
      </command_interface>
      <command_interface name="effort"/>
      <state_interface name="position"/>
      <state_interface name="velocity"/>
      <state_interface name="effort"/>
    </joint>
    <joint name="hip_pitch_r">
      <command_interface name="position">
        <param name="min">-3.14</param>
        <param name="max">3.14</param>
      </command_interface>
      <command_interface name="effort"/>
      <state_interface name="position"/>
      <state_interface name="velocity"/>
      <state_interface name="effort"/>
    </joint>
    <joint name="thigh_roll_l">
      <command_interface name="position">
        <param name="min">-3.14</param>
        <param name="max">3.14</param>
      </command_interface>
      <command_interface name="effort"/>
      <state_interface name="position"/>
      <state_interface name="velocity"/>
      <state_interface name="effort"/>
    </joint>
    <joint name="thigh_roll_r">
      <command_interface name="position">
        <param name="min">-3.14</param>
        <param name="max">3.14</param>
      </command_interface>
      <command_interface name="effort"/>
      <state_interface name="position"/>
      <state_interface name="velocity"/>
      <state_interface name="effort"/>
    </joint>
    <joint name="thigh_yaw_l">
      <command_interface name="position">
        <param name="min">-3.14</param>
        <param name="max">3.14</param>
      </command_interface>
      <command_interface name="effort"/>
      <state_interface name="position"/>
      <state_interface name="velocity"/>
      <state_interface name="effort"/>
    </joint>
    <joint name="thigh_yaw_r">
      <command_interface name="position">
        <param name="min">-3.14</param>
        <param name="max">3.14</param>
      </command_interface>
      <command_interface name="effort"/>
      <state_interface name="position"/>
      <state_interface name="velocity"/>
      <state_interface name="effort"/>
    </joint>
    <joint name="knee_pitch_l">
      <command_interface name="position">
        <param name="min">-3.14</param>
        <param name="max">3.14</param>
      </command_interface>
      <command_interface name="effort"/>
      <state_interface name="position"/>
      <state_interface name="velocity"/>
      <state_interface name="effort"/>
    </joint>
    <joint name="knee_pitch_r">
      <command_interface name="position">
        <param name="min">-3.14</param>
        <param name="max">3.14</param>
      </command_interface>
      <command_interface name="effort"/>
      <state_interface name="position"/>
      <state_interface name="velocity"/>
      <state_interface name="effort"/>
    </joint>
    <joint name="ankle_pitch_l">
      <command_interface name="position">
        <param name="min">-3.14</param>
        <param name="max">3.14</param>
      </command_interface>
      <command_interface name="effort"/>
      <state_interface name="position"/>
      <state_interface name="velocity"/>
      <state_interface name="effort"/>
    </joint>
    <joint name="ankle_pitch_r">
      <command_interface name="position">
        <param name="min">-3.14</param>
        <param name="max">3.14</param>
      </command_interface>
      <command_interface name="effort"/>
      <state_interface name="position"/>
      <state_interface name="velocity"/>
      <state_interface name="effort"/>
    </joint>
    <joint name="ankle_roll_l">
      <command_interface name="position">
        <param name="min">-3.14</param>
        <param name="max">3.14</param>
      </command_interface>
      <command_interface name="effort"/>
      <state_interface name="position"/>
      <state_interface name="velocity"/>
      <state_interface name="effort"/>
    </joint>
    <joint name="ankle_roll_r">
      <command_interface name="position">
        <param name="min">-3.14</param>
        <param name="max">3.14</param>
      </command_interface>
      <command_interface name="effort"/>
      <state_interface name="position"/>
      <state_interface name="velocity"/>
      <state_interface name="effort"/>
    </joint>
    <joint name="torso_pitch">
      <command_interface name="position">
        <param name="min">-3.14</param>
        <param name="max">3.14</param>
      </command_interface>
      <command_interface name="effort"/>
      <state_interface name="position"/>
      <state_interface name="velocity"/>
      <state_interface name="effort"/>
    </joint>
    <joint name="torso_roll">
      <command_interface name="position">
        <param name="min">-3.14</param>
        <param name="max">3.14</param>
      </command_interface>
      <command_interface name="effort"/>
      <state_interface name="position"/>
      <state_interface name="velocity"/>
      <state_interface name="effort"/>
    </joint>
    <joint name="torso_yaw">
      <command_interface name="position">
        <param name="min">-3.14</param>
        <param name="max">3.14</param>
      </command_interface>
      <command_interface name="effort"/>
      <state_interface name="position"/>
      <state_interface name="velocity"/>
      <state_interface name="effort"/>
    </joint>
    <joint name="shoulder_pitch_l">
      <command_interface name="position">
        <param name="min">-3.14</param>
        <param name="max">3.14</param>
      </command_interface>
      <command_interface name="effort"/>
      <state_interface name="position"/>
      <state_interface name="velocity"/>
      <state_interface name="effort"/>
    </joint>
    <joint name="shoulder_roll_l">
      <command_interface name="position">
        <param name="min">-3.14</param>
        <param name="max">3.14</param>
      </command_interface>
      <command_interface name="effort"/>
      <state_interface name="position"/>
      <state_interface name="velocity"/>
      <state_interface name="effort"/>
    </joint>
    <joint name="elbow_yaw_l">
      <command_interface name="position">
        <param name="min">-3.14</param>
        <param name="max">3.14</param>
      </command_interface>
      <command_interface name="effort"/>
      <state_interface name="position"/>
      <state_interface name="velocity"/>
      <state_interface name="effort"/>
    </joint>
    <joint name="elbow_pitch_l">
      <command_interface name="position">
        <param name="min">-3.14</param>
        <param name="max">3.14</param>
      </command_interface>
      <command_interface name="effort"/>
      <state_interface name="position"/>
      <state_interface name="velocity"/>
      <state_interface name="effort"/>
    </joint>
    <joint name="shoulder_pitch_r">
      <command_interface name="position">
        <param name="min">-3.14</param>
        <param name="max">3.14</param>
      </command_interface>
      <command_interface name="effort"/>
      <state_interface name="position"/>
      <state_interface name="velocity"/>
      <state_interface name="effort"/>
    </joint>
    <joint name="shoulder_roll_r">
      <command_interface name="position">
        <param name="min">-3.14</param>
        <param name="max">3.14</param>
      </command_interface>
      <command_interface name="effort"/>
      <state_interface name="position"/>
      <state_interface name="velocity"/>
      <state_interface name="effort"/>
    </joint>
    <joint name="elbow_yaw_r">
      <command_interface name="position">
        <param name="min">-3.14</param>
        <param name="max">3.14</param>
      </command_interface>
      <command_interface name="effort"/>
      <state_interface name="position"/>
      <state_interface name="velocity"/>
      <state_interface name="effort"/>
    </joint>
    <joint name="elbow_pitch_r">
      <command_interface name="position">
        <param name="min">-3.14</param>
        <param name="max">3.14</param>
      </command_interface>
      <command_interface name="effort"/>
      <state_interface name="position"/>
      <state_interface name="velocity"/>
      <state_interface name="effort"/>
    </joint>
  </ros2_control>
</robot>
